Workbook

Sheet Overview
A1: Vedha — Project Tracker
A2: Autonomous security-testing platform. End-to-end task tracker derived from the backend roadmap, strategy, and team playbook.
A3: Generated 2026-10-16. Single source of truth = 'Master Task List'. Fill Owner and Status columns there.
A5: How to use this workbook
A6: 1. Master Task List: every task with description, files, deliverable, verification, dependencies, effort. Edit Owner + Status here.
A7: 2. Phase Plan: the five delivery phases and which tasks belong to each; use for sprint planning.
A8: 3. Team Roster: the eight teams, their focus, and cross-team dependencies.
A9: 4. Status and priority cells have dropdowns. The summaries below recalc automatically from the Master Task List.
A11: Status summary | D11: Priority summary
A12: Status | B12: Count | D12: Priority | E12: Count | F12: Meaning
A13: Not Started | B13: =COUNTIF('Master Task List'!$M:$M,A13) -> 55 | D13: P0 | E13: =COUNTIF('Master Task List'!$D:$D,D13) -> 12 | F13: Safety-critical / pre-real-world
A14: In Progress | B14: =COUNTIF('Master Task List'!$M:$M,A14) -> 0 | D14: P1 | E14: =COUNTIF('Master Task List'!$D:$D,D14) -> 29 | F14: Robustness & reliability
A15: Blocked | B15: =COUNTIF('Master Task List'!$M:$M,A15) -> 0 | D15: P2 | E15: =COUNTIF('Master Task List'!$D:$D,D15) -> 12 | F15: Scale & quality
A16: In Review | B16: =COUNTIF('Master Task List'!$M:$M,A16) -> 0 | D16: - | E16: =COUNTIF('Master Task List'!$D:$D,D16) -> 3 | F16: Shared setup
A17: Done | B17: =COUNTIF('Master Task List'!$M:$M,A17) -> 1
A18: Total | B18: =COUNTA('Master Task List'!$A:$A)-1 -> 56 | D18: Percent complete | E18: =B17/B18 -> 0.017857143

Sheet Master Task List
A1: Task ID | B1: Team | C1: Phase | D1: Priority | E1: Title | F1: Description / What to build | G1: Key files | H1: Deliverable | I1: Verification / Acceptance | J1: Dependencies | K1: Effort | L1: Owner | M1: Status | N1: Notes
A2: T0.1 | B2: Shared | C2: P0: Foundations | D2: - | E2: Create root CLAUDE.md | F2: Add shared conventions + architecture map so every Claude Code session picks it up automatically. | G2: CLAUDE.md | H2: CLAUDE.md in repo root | I2: File exists; a fresh Claude Code session cites the build/test commands and conventions. | K2: S | M2: Done
A3: T0.2 | B3: Shared | C3: P0: Foundations | D3: - | E3: Agree integration branch & migration order | F3: Leads agree the integration branch name and a global ordering/numbering for DB migrations to avoid collisions. | G3: docs/ | H3: Written agreement in docs/ | I3: A single documented migration order exists; Teams 1/4/5 reference it. | K3: S | M3: Not Started
A4: T0.3 | B4: Shared | C4: P0: Foundations | D4: - | E4: Config-flag convention | F4: Agree the VEDHA_ flag naming and safe-default rule; add a short section to config docs. | G4: backend/pkg/config/config.go | H4: Documented convention | I4: All new runtime-behavior flags use VEDHA_ prefix with a safe default. | K4: S | M4: Not Started
A5: T1.1 | B5: 1 Safety & Policy | C5: P0: Safety Floor | D5: P0 | E5: Scope engine core package | F5: New package with Scope type (allowed CIDRs, domains w/ wildcards, ports, deny list, time window) and Check(target). | G5: backend/pkg/tools/scope/ | H5: scope package + table-driven tests | I5: go test ./pkg/tools/scope/ passes; cases cover IPv4/IPv6 CIDR, wildcard domains, deny precedence, ports, malformed input. | K5: M | M5: Not Started
A6: T1.2 | B6: 1 Safety & Policy | C6: P0: Safety Floor | D6: P0 | E6: Enforce scope at tool boundary | F6: Intercept terminal/pentester/browser calls, extract target, call Check; deny out-of-scope. Behind VEDHA_SCOPE_ENFORCEMENT (default off). | G6: backend/pkg/tools/executor.go, terminal.go, browser.go | H6: Enforcement wired behind flag | I6: With flag on and single-host scope, an out-of-scope target returns a deny string and the handler is never called (test double asserts). | J6: T1.1 | K6: M | M6: Not Started
A7: T1.3 | B7: 1 Safety & Policy | C7: P0: Safety Floor | D7: P0 | E7: Budgets & kill-switch | F7: Per-flow caps on cost(USD), iterations, wall-clock. Accumulate each loop; stop flow when a non-zero cap is exceeded. | G7: backend/pkg/providers/performer.go, controller/flow.go, config.go | H7: Budget enforcement + tests | I7: With a tiny VEDHA_MAX_FLOW_ITERATIONS the flow stops at the cap; defaults leave behavior unchanged. | K7: M | M7: Not Started
A8: T1.4 | B8: 1 Safety & Policy | C8: P3: Product & Trust | D8: P1 | E8: Human-approval gate | F8: Gate high-impact actions (confirmed exploitation, credential use, destructive cmds) via the existing ask tool. | G8: backend/pkg/tools/executor.go, tools.go | H8: Approval gate behind flag | I8: A flagged high-impact action pauses for approval and does not execute until approved (test). | J8: T1.2 | K8: M | M8: Not Started
A9: T1.5 | B9: 1 Safety & Policy | C9: P0: Safety Floor | D9: P0 | E9: Scope schema: migration + API inputs | F9: Add scope JSON column on flows; extend GraphQL/REST create-flow inputs to accept a scope. | G9: backend/migrations/sql/, backend/pkg/graph/, server/ | H9: Migration + API field | I9: Migration applies up/down; a flow can be created with a scope via API and it persists. | J9: T1.1,T0.2 | K9: M | M9: Not Started
A10: T1.6 | B10: 1 Safety & Policy | C10: P0: Safety Floor | D10: P0 | E10: Policy docs + target-parsing threat model | F10: Document policy format; threat-model the target extraction so obfuscated commands cannot evade the check (deny-on-uncertainty). | G10: docs/ | H10: Doc + threat model | I10: Security reviewer signs off; ambiguous targets default to deny in tests. | J10: T1.2 | K10: S | M10: Not Started
A11: T2.1 | B11: 2 Sandbox & Infra | C11: P0: Safety Floor | D11: P0 | E11: Container capability hardening | F11: Drop all caps, add back NET_RAW always + NET_ADMIN only when enabled; set no-new-privileges, seccomp. | G11: backend/pkg/docker/client.go | H11: Hardened container create | I11: nmap SYN scan still works; capsh --print shows reduced caps; existing toolchain unaffected. | K11: M | M11: Not Started
A12: T2.2 | B12: 2 Sandbox & Infra | C12: P0: Safety Floor | D12: P0 | E12: Sandbox resource limits | F12: Set Memory, NanoCPUs, PidsLimit from VEDHA_SANDBOX_* config. | G12: backend/pkg/docker/client.go, config.go | H12: Resource limits applied | I12: A fork bomb / memory hog in the sandbox is bounded; limits visible via docker inspect. | K12: S | M12: Not Started
A13: T2.3 | B13: 2 Sandbox & Infra | C13: P0: Safety Floor | D13: P0 | E13: Remove/proxy host Docker socket | F13: Eliminate raw /var/run/docker.sock mount under DOCKER_INSIDE, or replace with a restricted socket proxy. | G13: backend/pkg/docker/client.go | H13: Decision + implementation | I13: No raw host socket is exposed to agent-run code; decision documented. | K13: M | M13: Not Started
A14: T2.4 | B14: 2 Sandbox & Infra | C14: P1: Reliability | D14: P1 | E14: Terminal: honest timeout ceiling | F14: Honor documented 1200s ceiling instead of silently clamping >20min down to 5min. | G14: backend/pkg/tools/terminal.go | H14: Fixed timeout logic + tests | I14: A 30-min timeout runs 30 min; clamp logic unit-tested. | K14: S | M14: Not Started
A15: T2.5 | B15: 2 Sandbox & Infra | C15: P1: Reliability | D15: P1 | E15: Terminal: trackable detached execs | F15: Registry of background executions keyed by id so output is retrievable and they are cancellable. | G15: backend/pkg/tools/terminal.go | H15: Detach registry + tests | I15: A detached command's output can be fetched later and the job cancelled. | K15: M | M15: Not Started
A16: T2.6 | B16: 2 Sandbox & Infra | C16: P1: Reliability | D16: P1 | E16: Terminal: surface exit codes | F16: Read exit code from ContainerExecInspect and include it in results. | G16: backend/pkg/tools/terminal.go | H16: Exit code in result + tests | I16: A failing command reports non-zero; empty output no longer masquerades as success. | K16: S | M16: Not Started
A17: T2.7 | B17: 2 Sandbox & Infra | C17: P0: Foundations | D17: P1 | E17: Azure IaC (Bicep) | F17: Bicep modules: AKS/Container Apps, session pool, Postgres+pgvector, AI Search, Key Vault, Entra app, VNet+NSG+Firewall, Front Door+WAF. | G17: deploy/ | H17: Validated Bicep + README | I17: az bicep build succeeds with no errors; README documents deploy commands. | K17: L | M17: Not Started
A18: T2.8 | B18: 2 Sandbox & Infra | C18: P3: Product & Trust | D18: P1 | E18: Azure Container Apps sandbox adapter | F18: Adapter so tool execution can target ACA Dynamic Sessions/Sandboxes (microVM) instead of raw Docker. | G18: backend/pkg/docker/ (interface), new adapter | H18: Pluggable sandbox backend | I18: Same tool run succeeds against the ACA backend in staging; Docker backend still works. | J18: T2.7 | K18: L | M18: Not Started
A19: T2.9 | B19: 2 Sandbox & Infra | C19: P0: Safety Floor | D19: P0 | E19: Network egress enforcement | F19: Default-deny outbound; allow only in-scope targets + required infra via NSG/Azure Firewall / local nftables sidecar. | G19: backend/pkg/docker/client.go, deploy/ | H19: Egress policy aligned to scope | I19: Out-of-scope egress from the sandbox is blocked at the network, mirroring T1.1 allowlist. | J19: T1.1,T2.7 | K19: L | M19: Not Started
A20: T2.10 | B20: 2 Sandbox & Infra | C20: P4: Scale & GA | D20: P2 | E20: Sandbox fleet runbook | F20: Operational runbook for provisioning, scaling, and tearing down sandboxes. | G20: docs/ | H20: Runbook | I20: On-call can follow the runbook to operate the fleet. | J20: T2.8 | K20: S | M20: Not Started
A21: T3.1 | B21: 3 Providers & Models | C21: P1: Reliability | D21: P1 | E21: Per-role model config update | F21: Set best-fit model per tier across anthropic/openai/gemini configs (deep/orchestration/cheap). | G21: backend/pkg/providers/*/config.yml | H21: Updated role->model maps | I21: Configs load/validate; testAgent passes for each role with staging keys. | K21: M | M21: Not Started
A22: T3.2 | B22: 3 Providers & Models | C22: P1: Reliability | D22: P1 | E22: Bedrock tiering + reasoning | F22: Replace single-model-for-all with real tiering; add reasoning blocks for thinking-capable models. | G22: backend/pkg/providers/bedrock/config.yml | H22: Tiered Bedrock config | I22: Bedrock roles use tier-appropriate models; reasoning blocks present; tests pass. | J22: T3.1 | K22: S | M22: Not Started
A23: T3.3 | B23: 3 Providers & Models | C23: P1: Reliability | D23: P1 | E23: Reconcile default-model constants | F23: Align hardcoded Go default model constants with the YAML so they don't silently diverge. | G23: backend/pkg/providers/*/*.go | H23: Consistent defaults | I23: Grep shows Go defaults match a real role model; no orphan defaults (e.g. gemini-2.5-flash). | J23: T3.1 | K23: S | M23: Not Started
A24: T3.4 | B24: 3 Providers & Models | C24: P1: Reliability | D24: P1 | E24: Model fallback & failover | F24: Ordered fallback models (+ optional fallback provider) tried on retryable/capacity failure before abort. Flag VEDHA_MODEL_FALLBACK. | G24: backend/pkg/providers/provider/wrapper.go, performer.go, pconfig | H24: Fallback chain + tests | I24: Fake primary returns 429 past budget -> task completes on fallback model. | K24: M | M24: Not Started
A25: T3.5 | B25: 3 Providers & Models | C25: P1: Reliability | D25: P1 | E25: Token-aware context management | F25: Per-model context-window table + token counting drives summarization; byte caps become fallback for unknown models. | G25: backend/pkg/providers/provider.go, csum/ | H25: Token-aware limits + tests | I25: A long chat stays under the model's real window; no overflow; unknown model falls back to byte caps. | K25: L | M25: Not Started
A26: T3.6 | B26: 3 Providers & Models | C26: P1: Reliability | D26: P1 | E26: Proactive rate limiting + jittered backoff | F26: Client-side concurrency/token-rate limiter per provider; jittered exponential backoff; robust 429 detection. | G26: backend/pkg/providers/provider/wrapper.go | H26: Limiter + backoff + tests | I26: Parallel sub-agents do not burst past provider limits in a load test; backoff has jitter. | K26: M | M26: Not Started
A27: T3.7 | B27: 3 Providers & Models | C27: P1: Reliability | D27: P1 | E27: Embedding upgrade + version guard | F27: Default to text-embedding-3-large (configurable); tag vectors with embedding-model version; refuse mixed-model search. | G27: backend/pkg/providers/embeddings/embedder.go | H27: Upgrade + version guard | I27: Switching models surfaces the version guard, not silent bad matches; guard unit-tested. | K27: M | M27: Not Started
A28: T3.8 | B28: 3 Providers & Models | C28: P2: Scale & Quality | D28: P2 | E28: Single source of truth for prices | F28: Reconcile config.yml vs models.yml prices; document the update process. | G28: backend/pkg/providers/*/config.yml, models.yml | H28: Reconciled prices + doc | I28: No price disagreements between the two files; cost accounting matches provider pricing. | J28: T3.1 | K28: S | M28: Not Started
A29: T4.1 | B29: 4 Memory & Data | C29: P0: Foundations | D29: P0 | E29: Typed findings & evidence model | F29: Migration for findings + evidence tables; sqlc queries; Go model following existing patterns. | G29: backend/migrations/sql/, sqlc/models/, pkg/database/ | H29: Findings schema + queries | I29: Migration up/down clean; a finding round-trips with all typed fields; query tests pass. | J29: T0.2 | K29: L | M29: Not Started
A30: T4.2 | B30: 4 Memory & Data | C30: P1: Reliability | D30: P1 | E30: report_finding barrier tool | F30: New validated barrier tool for agents to record a typed finding. | G30: backend/pkg/tools/ | H30: report_finding tool | I30: Agent records a finding via the tool; schema validation rejects malformed findings. | J30: T4.1 | K30: M | M30: Not Started
A31: T4.3 | B31: 4 Memory & Data | C31: P2: Scale & Quality | D31: P1 | E31: Managed pgvector schema | F31: Bring embedding table under migration control with pinned dimension + HNSW index. | G31: backend/migrations/sql/ | H31: Managed vector schema | I31: Migration applies; similarity queries use the HNSW index (check query plan). | K31: M | M31: Not Started
A32: T4.4 | B32: 4 Memory & Data | C32: P2: Scale & Quality | D32: P1 | E32: RAG reranking | F32: Reranking after similarity search behind VEDHA_RERANK; local + Azure AI Search implementations. | G32: backend/pkg/tools/memory.go | H32: Reranker interface + 2 impls | I32: With rerank on, results return in reranker order; fake-reranker test asserts reorder. | K32: M | M32: Not Started
A33: T4.5 | B33: 4 Memory & Data | C33: P3: Product & Trust | D33: P2 | E33: Attack-path graph schema | F33: Unified graph (assets, creds, findings, relationships) on Graphiti/Neo4j spanning web+network+cloud. | G33: backend/pkg/graphiti/, templates/graphiti/ | H33: Graph schema + writers | I33: A web foothold and a network finding link in one graph; traversal returns the chain. | J33: T4.1 | K33: L | M33: Not Started
A34: T4.6 | B34: 4 Memory & Data | C34: P2: Scale & Quality | D34: P2 | E34: Log retention & partitioning | F34: Time-based partitioning + retention for termlogs/msglogs/toolcalls. | G34: backend/migrations/sql/ | H34: Partitioning + retention | I34: Old rows age out per policy; high-volume tables partitioned; no unbounded growth. | K34: M | M34: Not Started
A35: T4.7 | B35: 4 Memory & Data | C35: P1: Reliability | D35: P1 | E35: Re-embedding migration | F35: Migration/tooling to re-embed stored vectors when the embedding model changes. | G35: backend/migrations/sql/, tooling | H35: Re-embedding path | I35: Running it re-embeds existing content under the new model and updates version tags. | J35: T3.7,T4.3 | K35: M | M35: Not Started
A36: T4.8 | B36: 4 Memory & Data | C36: P0: Foundations | D36: P1 | E36: Findings taxonomy | F36: Define vulnerability classes, severity scale, CVSS usage with security input. | G36: docs/ | H36: Taxonomy doc | I36: Taxonomy agreed and referenced by T4.1 schema enums. | K36: S | M36: Not Started
A37: T5.1 | B37: 5 Platform & Identity | C37: P0: Foundations | D37: P0 | E37: Authorization characterization tests | F37: Tests locking in current GraphQL/permission authz behavior before changing it. | G37: backend/pkg/graph/context.go, server/auth/permissions.go | H37: Authz test suite | I37: Tests cover cross-user denial, admin bypass, *.admin regex, missing-perm denial; all pass on current code. | K37: M | M37: Not Started
A38: T5.2 | B38: 5 Platform & Identity | C38: P3: Product & Trust | D38: P1 | E38: Entra ID OIDC provider | F38: Add Microsoft Entra ID OIDC alongside Google/GitHub; map Entra groups to roles. Gated by OAUTH_ENTRA_*. | G38: backend/pkg/server/oauth/ | H38: Entra provider + tests | I38: An Entra login creates/links a user with the mapped role; existing providers unaffected. | J38: T5.1 | K38: M | M38: Not Started
A39: T5.3 | B39: 5 Platform & Identity | C39: P3: Product & Trust | D39: P2 | E39: SAML seam | F39: Clean extension point for SAML on top of the OIDC work. | G39: backend/pkg/server/oauth/, auth/ | H39: SAML interface seam | I39: SAML can be added without reworking the auth flow; seam documented. | J39: T5.2 | K39: S | M39: Not Started
A40: T5.4 | B40: 5 Platform & Identity | C40: P3: Product & Trust | D40: P1 | E40: Tenancy & isolation | F40: tenants table + tenant_id on users/flows; enforce isolation in ownership checks; default single tenant. | G40: backend/migrations/sql/, pkg/graph/context.go | H40: Tenancy + isolation | I40: User in tenant A cannot see tenant B flows (test); existing installs migrate to one tenant. | J40: T5.1,T0.2 | K40: L | M40: Not Started
...

Sheet Phase Plan
A1: Delivery Phases
A2: Sequencing for ~9-12 months to enterprise GA with a 3-8 person senior team. Durations are planning ballparks, not commitments.
A4: Phase | B4: Duration (ballpark) | C4: Team size | D4: Goal | E4: Exit / success target | F4: Task count
A5: P0: Foundations | B5: ~1 month | C5: 2-3 | D5: Provider abstraction, sandbox skeleton, safety-layer + findings-model + eval scaffolding, CI. | E5: One agent runs one safe, scoped, evidenced finding end to end. | F5: =COUNTIF('Master Task List'!$C:$C,A5) -> 11
A6: P0: Safety Floor | B6: within month 1-2 | C6: 3-5 | D6: Scope engine, egress, hardening, resource limits, budgets, socket, secrets. | E6: Nothing runs against a real network until this lands. | F6: =COUNTIF('Master Task List'!$C:$C,A6) -> 9
A7: P1: Reliability | B7: 2-3 months | C7: 3-6 | D7: Model upgrade + fallback, token-aware context, terminal fixes, rate limiting, embeddings. | E7: Long autonomous runs survive provider blips; correct exit/timeout semantics. | F7: =COUNTIF('Master Task List'!$C:$C,A7) -> 13
A8: P2: Scale & Quality | B8: parallel + 2-3 months | C8: 4-6 | D8: Vector schema, reranking, retention, Docker/memory tests, price reconciliation. | E8: Managed data layer; risky core under test. | F8: =COUNTIF('Master Task List'!$C:$C,A8) -> 6
A9: P3: Product & Trust | B9: 3-4 months | C9: 5-8 | D9: Findings/reporting, verified proof, diffing, Entra SSO, tenancy, audit, integrations, attack graph, ACA sandbox. | E9: Pass a design partner security review; measurable FP rate. | F9: =COUNTIF('Master Task List'!$C:$C,A9) -> 13
A10: P4: Scale & GA | B10: ongoing | C10: 8+ | D10: Benchmark corpus, more integrations, runbooks, docs, managed cloud tier. | E10: Paying customers, SLA, continuous engagements at scale. | F10: =COUNTIF('Master Task List'!$C:$C,A10) -> 4

Sheet Team Roster
A1: Teams & Dependencies
A2: Eight workstreams. Each team owns its section of the playbook (docs/VEDHA_TEAM_PLAYBOOK.md).
A4: Team | B4: Focus | C4: Key packages | D4: Depends on | E4: Blocks | F4: Task count
A5: Shared | B5: Setup, conventions, migration ordering | C5: CLAUDE.md, config | D5: - | E5: All teams | F5: =COUNTIF('Master Task List'!$B:$B,A5) -> 3
A6: 1 Safety & Policy | B6: Scope engine, budgets, approval gates | C6: pkg/tools/scope, executor | D6: Shared | E6: Team 2 egress | F6: =COUNTIF('Master Task List'!$B:$B,A6) -> 6
A7: 2 Sandbox & Infra | B7: Container hardening, terminal, Azure IaC | C7: pkg/docker, pkg/tools/terminal, deploy | D7: Team 1 (scope) | E7: Team 7 docker tests | F7: =COUNTIF('Master Task List'!$B:$B,A7) -> 10
A8: 3 Providers & Models | B8: Models, fallback, context, embeddings | C8: pkg/providers | D8: - | E8: Team 4 (embeddings) | F8: =COUNTIF('Master Task List'!$B:$B,A8) -> 8
A9: 4 Memory & Data | B9: Findings model, vector schema, graph | C9: migrations, sqlc, pkg/graphiti | D9: Shared | E9: Teams 6,7 | F9: =COUNTIF('Master Task List'!$B:$B,A9) -> 8
A10: 5 Platform & Identity | B10: SSO, tenancy, audit, authz tests | C10: pkg/server, pkg/graph | D10: Shared | E10: - | F10: =COUNTIF('Master Task List'!$B:$B,A10) -> 6
A11: 6 Reporting & Integrations | B11: Reports, proof, diffing, connectors | C11: reporter, pkg/integrations | D11: Team 4 | E11: - | F11: =COUNTIF('Master Task List'!$B:$B,A11) -> 6
A12: 7 Eval & QA | B12: Eval harness, core tests, CI | C12: cmd/eval, .github/workflows | D12: Team 4 (ground truth) | E12: All (gates) | F12: =COUNTIF('Master Task List'!$B:$B,A12) -> 9
